<?xml version="1.0"?>
<robot name="my_wheelchair">

  <!-- **************************************** 0. References ***************************************** -->

  <!--   
  The following is a chair made for the powered wheelchair base, created above.
  This is my own model and design. Although it is basic, the model was planned
  using weights and sizes of the Jazzy Select 6 powered wheelchair.
  -->

  <!-- ******************************************* 0. END ********************************************* -->

  <!-- **************************************** 1. Materials ****************************************** -->

  <!--   
  These colours are sourced from the material folder in Gazebo.
  Location:

  (REF how this was discovered)
  -->

  <gazebo reference="base_link">
	<material>Gazebo/Red</material>
  </gazebo>

  <gazebo reference="chair_seat">
	<material>Gazebo/Black</material>
  </gazebo>

  <gazebo reference="chair_back">
	<material>Gazebo/Black</material>
  </gazebo>

  <gazebo reference="chair_spine">
	<material>Gazebo/Black</material>
  </gazebo>

  <gazebo reference="arm_left">
	<material>Gazebo/Black</material>
  </gazebo>

  <gazebo reference="arm_right">
	<material>Gazebo/Black</material>
  </gazebo>

  <gazebo reference="foot_rest">
	<material>Gazebo/Black</material>
  </gazebo>

  <gazebo reference="front_left_caster">
	<material>Gazebo/Red</material>
  </gazebo>

  <gazebo reference="front_left_wheel">
	<material>Gazebo/Black</material>
  </gazebo>

  <gazebo reference="front_right_caster">
	<material>Gazebo/Red</material>
  </gazebo>

  <gazebo reference="front_right_wheel">
	<material>Gazebo/Black</material>
  </gazebo>

  <gazebo reference="back_left_caster">
	<material>Gazebo/Red</material>
  </gazebo>

  <gazebo reference="back_left_wheel">
	<material>Gazebo/Black</material>
  </gazebo>

  <gazebo reference="back_right_caster">
	<material>Gazebo/Red</material>
  </gazebo>

  <gazebo reference="back_right_wheel">
	<material>Gazebo/Black</material>
  </gazebo>

  <gazebo reference="left_wheel">
	<material>Gazebo/Black</material>
  </gazebo>

  <gazebo reference="right_wheel">
	<material>Gazebo/Black</material>
  </gazebo>

  <gazebo reference="hokuyo_main">
	<material>Gazebo/Black</material>
  </gazebo>

  <gazebo reference="hokuyo_main_pointer">
	<material>Gazebo/Blue</material>
  </gazebo>

  <!-- ****************************************** 1. END ****************************************** -->

  <!-- *************************************** 2. BASE_LINK *************************************** -->

  <!--   
  The building of the URDF wheelchair began with an indepth tutorial to create a
  diffrential drive tortoisebot, the first Turtlebot.

  (REF book and pages)

  The tutorial demonstrated how to create a base_link, two active wheels and one
  passive caster wheel. Once the base concepts were understood, a more complex 
  design could be pursued.
  -->

  <link name="base_link">
	<visual>
	  <geometry>
		<box size="0.5 0.4 0.2"/>
	  </geometry> 
	</visual>
	
	<collision>
	  <geometry>
		<box size="0.5 0.4 0.2"/>
	  </geometry>
	</collision>

	<inertial>
	  <mass value="1.0"/>
	  <inertia ixx="0.015" iyy="0.0375" izz="0.0375" ixy="0" ixz="0" iyz="0"/>
	</inertial>
  </link>

  <!-- ****************************************** 2. END ****************************************** -->

  <!-- ************************************* 3. PASSIVE WHEELS ************************************ -->

  <!--   
  The following is a chair made for the powered wheelchair base, created above.
  This is my own model and design. Although it is basic, the model was planned
  using weights and sizes of the Jazzy Select 6 powered wheelchair.
  -->

  <!--   
	TEMPLATE OF GENERAL FUNCTIONALITY
  -->

  <!-- ************************************** 3a. Front Left ************************************** -->

  <link name="front_left_caster">
	<visual>
	  <geometry>
		<box size="0.1 0.1 0.15"/>
	  </geometry>
	</visual>

	<collision>
	  <geometry>
		<box size="0.1 0.1 0.15"/>
	  </geometry>
	</collision>

	<inertial>
	  <mass value="0.1"/>
	  <inertia ixx="0.00083" iyy="0.00083" izz="0.000167" ixy="0" ixz="0" iyz="0"/>
	</inertial>
  </link>

  <joint name="front_left_caster_joint" type="continuous">
	<axis xyz="0 0 1"/>
	<parent link="base_link"/>
	<child link="front_left_caster"/>
	<origin rpy="-0 0 0" xyz="0.3 0.2 -0.05"/>
  </joint>

  <link name="front_left_wheel">
	<visual>
	  <geometry>
		<cylinder length="0.05" radius="0.065"/>
	  </geometry>
	</visual>

	<collision>
	  <geometry>
		<cylinder length="0.05" radius="0.065"/>
	  </geometry>
	</collision>

	<inertial>
	  <mass value="0.1"/>
	  <inertia ixx="5.1458e-5" iyy="5.1458e-5" izz="6.125e-5" ixy="0" ixz="0" iyz="0"/>
	</inertial>
  </link>

  <joint name="front_left_wheel_joint" type="continuous">
	<axis xyz="0 0 1"/>
	<parent link="front_left_caster"/>
	<child link="front_left_wheel"/>
	<origin rpy="-1.5708 0 0" xyz="0.05 0 -0.075"/>
  </joint>

  <!-- ************************************* 3b. Front Right ************************************** -->

  <link name="front_right_caster">
	<visual>
	  <geometry>
		<box size="0.1 0.1 0.15"/>
	  </geometry>
	</visual>

	<collision>
	  <geometry>
		<box size="0.1 0.1 0.15"/>
	  </geometry>
	</collision>

	<inertial>
	  <mass value="0.1"/>
	  <inertia ixx="0.00083" iyy="0.00083" izz="0.000167" ixy="0" ixz="0" iyz="0"/>
	</inertial>
  </link>

  <joint name="front_right_caster_joint" type="continuous">
	<axis xyz="0 0 1"/>
	<parent link="base_link"/>
	<child link="front_right_caster"/>
	<origin rpy="0 0 0" xyz="0.3 -0.2 -0.05"/>
  </joint>

  <link name="front_right_wheel">
	<visual>
	  <geometry>
		<cylinder length="0.05" radius="0.065"/>
	  </geometry>
	</visual>

	<collision>
	  <geometry>
		<cylinder length="0.05" radius="0.065"/>
	  </geometry>
	</collision>

	<inertial>
	  <mass value="0.1"/>
	  <inertia ixx="5.1458e-5" iyy="5.1458e-5" izz="6.125e-5" ixy="0" ixz="0" iyz="0"/>
	</inertial>
  </link>

  <joint name="front_right_wheel_joint" type="continuous">
	<axis xyz="0 0 1"/>
	<parent link="front_right_caster"/>
	<child link="front_right_wheel"/>
	<origin rpy="-1.5708 0 0" xyz="0.05 0 -0.075"/>
  </joint>

  <!-- ************************************* 3c. Back Left ************************************** -->

  <link name="back_left_caster">
	<visual>
	  <geometry>
		<box size="0.1 0.1 0.15"/>
	  </geometry>
	</visual>

	<collision>
	  <geometry>
		<box size="0.1 0.1 0.15"/>
	  </geometry>
	</collision>

	<inertial>
	  <mass value="0.1"/>
	  <inertia ixx="0.00083" iyy="0.00083" izz="0.000167" ixy="0" ixz="0" iyz="0"/>
	</inertial>
  </link>

  <joint name="back_left_caster_joint" type="continuous">
	<axis xyz="0 0 1"/>
	<parent link="base_link"/>
	<child link="back_left_caster"/>
	<origin rpy="0 0 0" xyz="-0.3 0.2 -0.05"/>
  </joint>

  <link name="back_left_wheel">
	<visual>
	  <geometry>
		<cylinder length="0.05" radius="0.065"/>
	  </geometry>
	</visual>

	<collision>
	  <geometry>
		<cylinder length="0.05" radius="0.065"/>
	  </geometry>
	</collision>

	<inertial>
	  <mass value="0.1"/>
	  <inertia ixx="5.1458e-5" iyy="5.1458e-5" izz="6.125e-5" ixy="0" ixz="0" iyz="0"/>
	</inertial>
  </link>

  <joint name="back_left_wheel_joint" type="continuous">
	<axis xyz="0 0 1"/>
	<parent link="back_left_caster"/>
	<child link="back_left_wheel"/>
	<origin rpy="-1.5708 0 0" xyz="0.05 0 -0.075"/>
  </joint>

  <!-- ************************************* 3d. Back Right ************************************** -->

  <link name="back_right_caster">
	<visual>
	  <geometry>
		<box size="0.1 0.1 0.15"/>
	  </geometry>
	</visual>

	<collision>
	  <geometry>
		<box size="0.1 0.1 0.15"/>
	  </geometry>
	</collision>

	<inertial>
	  <mass value="0.1"/>
	  <inertia ixx="0.00083" iyy="0.00083" izz="0.000167" ixy="0" ixz="0" iyz="0"/>
	</inertial>
  </link>

  <joint name="back_right_caster_joint" type="continuous">
	<axis xyz="0 0 1"/>
	<parent link="base_link"/>
	<child link="back_right_caster"/>
	<origin rpy="0 0 0" xyz="-0.3 -0.2 -0.05"/>
  </joint>

  <link name="back_right_wheel">
	<visual>
	  <geometry>
		<cylinder length="0.05" radius="0.065"/>
	  </geometry>
	</visual>

	<collision>
	  <geometry>
		<cylinder length="0.05" radius="0.065"/>
	  </geometry>
	</collision>

	<inertial>
	  <mass value="0.1"/>
	  <inertia ixx="5.1458e-5" iyy="5.1458e-5" izz="6.125e-5" ixy="0" ixz="0" iyz="0"/>
	</inertial>
  </link>

  <joint name="back_right_wheel_joint" type="continuous">
	<axis xyz="0 0 1"/>
	<parent link="back_right_caster"/>
	<child link="back_right_wheel"/>
	<origin rpy="-1.5708 0 0" xyz="0.05 0 -0.075"/>
  </joint>

  <!-- ********************************* 3e. Joint State Publisher ******************************** -->

  <!--   
  The following is a chair made for the powered wheelchair base, created above.
  This is my own model and design. Although it is basic, the model was planned
  using weights and sizes of the Jazzy Select 6 powered wheelchair.
  -->

  <gazebo>
	<plugin name="joint_state_publisher" filename="libgazebo_ros_joint_state_publisher.so">
	  <jointName>front_left_caster_joint, front_left_wheel_joint</jointName>
	</plugin>
  </gazebo>

  <gazebo>
	<plugin name="joint_state_publisher" filename="libgazebo_ros_joint_state_publisher.so">
	  <jointName>front_right_caster_joint, front_right_wheel_joint</jointName>
	</plugin>
  </gazebo>

  <gazebo>
	<plugin name="joint_state_publisher" filename="libgazebo_ros_joint_state_publisher.so">
	  <jointName>back_left_caster_joint, back_left_wheel_joint</jointName>
	</plugin>
  </gazebo>

  <gazebo>
	<plugin name="joint_state_publisher" filename="libgazebo_ros_joint_state_publisher.so">
	  <jointName>back_right_caster_joint, back_right_wheel_joint</jointName>
	</plugin>
  </gazebo>

  <!-- **************************************** 3. END ******************************************** -->

  <!-- *********************************** 4. ACTIVE WHEELS *************************************** -->

  <!--   
  The following is a chair made for the powered wheelchair base, created above.
  This is my own model and design. Although it is basic, the model was planned
  using weights and sizes of the Jazzy Select 6 powered wheelchair.
  -->

  <!-- ************************************ 4a. Left Wheel **************************************** -->

  <link name="left_wheel">
	<visual>
	  <geometry>
		<cylinder length="0.075" radius="0.125"/>
	  </geometry>
	  <material name="black"/>
	</visual>

	<collision>
	  <geometry>
		<cylinder length="0.075" radius="0.125"/>
	  </geometry>
	</collision>

	<inertial>
	  <mass value="0.1"/>
	  <inertia ixx="5.1458e-5" iyy="5.1458e-5" izz="6.125e-5" ixy="0" ixz="0" iyz="0"/>
	</inertial>
  </link>

  <joint name="left_wheel_joint" type="continuous">
	<axis xyz="0 0 1"/>
	<parent link="base_link"/>
	<child link="left_wheel"/>
	<origin rpy="-1.5708 0 0" xyz="0.0 0.25 -.065"/>
  </joint>

  <!-- ************************************* 4b. Right Wheel ************************************** -->

  <link name="right_wheel">
	<visual>
	  <geometry>
		<cylinder length="0.075" radius="0.125"/>
	  </geometry>
	</visual>

	<collision>
	  <geometry>
		<cylinder length="0.075" radius="0.125"/>
	  </geometry>
	</collision>

	<inertial>
	  <mass value="0.1"/>
	  <inertia ixx="5.1458e-5" iyy="5.1458e-5" izz="6.125e-5" ixy="0" ixz="0" iyz="0"/>
	</inertial>
  </link>

  <joint name="right_wheel_joint" type="continuous">
	<axis xyz="0 0 1"/>
	<parent link="base_link"/>
	<child link="right_wheel"/>
	<origin rpy="-1.5708 0 0" xyz="0.0 -0.25 -.065"/>
  </joint>

  <!-- ****************************************** 4. END ****************************************** -->

  <!-- ******************************** 5. DIFFERENTIAL DRIVE PLUGIN ****************************** -->

  <!--   
  The following is a chair made for the powered wheelchair base, created above.
  This is my own model and design. Although it is basic, the model was planned
  using weights and sizes of the Jazzy Select 6 powered wheelchair.
  -->

  <gazebo>

	<plugin name="differential_drive_controller" filename="libgazebo_ros_diff_drive.so">
	  <leftJoint>right_wheel_joint</leftJoint>
	  <rightJoint>left_wheel_joint</rightJoint>
	  <robotBaseFrame>base_link</robotBaseFrame>
	  <wheelSeparation>0.25</wheelSeparation>
	  <wheelDiameter>0.07</wheelDiameter>
	  <publishWheelJointState>true</publishWheelJointState>
	</plugin>

  </gazebo>


  <!-- ****************************************** 5. END ****************************************** -->

  <!-- *********************************** 6. WHEELCHAIR DETAILS ********************************** -->

  <!--   
  The following is a chair made for the powered wheelchair base, created above.
  This is my own model and design. Although it is basic, the model was planned
  using weights and sizes of the Jazzy Select 6 powered wheelchair.
  -->

  <!-- ************************************** 6a. Foot Rest ************************************** -->

  <link name="foot_rest">
	<visual>
	  <geometry>
		<box size="0.2 0.25 0.01"/>
	  </geometry> 	  
	</visual>

	<collision>
	  <geometry>
		<box size="0.2 0.25 0.01"/>
	  </geometry>
	</collision>

	<inertial>
	  <mass value="0.1"/>
	  <inertia ixx="0.015" iyy="0.0375" izz="0.0375" ixy="0" ixz="0" iyz="0"/>
	</inertial>
  </link>

  <joint name="foot_rest_joint" type="fixed">
	<axis xyz="1 0 0"/>
	<parent link="base_link"/>
	<child link="foot_rest"/>
	<origin rpy="0 0 0" xyz="0.35 0.0 -0.1"/>
  </joint>

  <!-- ************************************ 6b. Chair Piller ************************************* -->
  
  <link name="chair_pillar">
	<visual>
	  <geometry>
		<cylinder length="0.2" radius="0.075"/>
	  </geometry>
	</visual>
	
	<collision>
	  <geometry>
		<cylinder length="0.2" radius="0.075"/>
	  </geometry>
	</collision>

	<inertial>
	  <mass value="0.1"/>
	  <inertia ixx="0.015" iyy="0.0375" izz="0.0375" ixy="0" ixz="0" iyz="0"/>
	</inertial>
  </link>

  <joint name="chair_pillar_joint" type="fixed">
	<axis xyz="0 1 0"/>
	<parent link="base_link"/>
	<child link="chair_pillar"/>
	<origin rpy="0 0 0" xyz="0.0 0.0  0.175"/>
  </joint>

  <!-- *********************************** 6c. Cushioned Seat ************************************ -->

  <link name="chair_seat">
	<visual>
	  <geometry>
		<box size="0.6 0.45 0.1"/>
	  </geometry> 	  
	</visual>
	
	<collision>
	  <geometry>
		<box size="0.6 0.5 0.1"/>
	  </geometry>
	</collision>

	<inertial>
	  <mass value="0.1"/>
	  <inertia ixx="0.015" iyy="0.0375" izz="0.0375" ixy="0" ixz="0" iyz="0"/>
	</inertial>
  </link>

  <joint name="chair_seat_joint" type="fixed">
	<axis xyz="1 0 0"/>
	<parent link="chair_pillar"/>
	<child link="chair_seat"/>
	<origin rpy="0 0 0" xyz="0.0 0.0 0.1"/>
  </joint>

  <!-- ********************************** 6d. Connecting Spine ************************************ -->

  <link name="chair_spine">
	<visual>
	  <geometry>
		<box size="0.035 0.1 0.2"/>
	  </geometry> 	  
	</visual>
	
	<collision>
	  <geometry>
		<box size="0.035 0.1 0.2"/>
	  </geometry>
	</collision>

	<inertial>
	  <mass value="0.1"/>
	  <inertia ixx="0.015" iyy="0.0375" izz="0.0375" ixy="0" ixz="0" iyz="0"/>
	</inertial>
  </link>

  <joint name="chair_spine_joint" type="fixed">
	<axis xyz="1 0 0"/>
	<parent link="chair_seat"/>
	<child link="chair_spine"/>
	<origin rpy="0 0 0" xyz="-0.3 0.0 0.1"/>
  </joint>

  <!-- *********************************** 6e. Cushioned Back ************************************ -->

  <link name="chair_back">
	<visual>
	  <geometry>
		<box size="0.1 0.45 0.5"/>
	  </geometry> 	  
	</visual>
	
	<collision>
	  <geometry>
		<box size="0.2 0.25 0.6"/>
	  </geometry>
	</collision>

	<inertial>
	  <mass value="0.1"/>
	  <inertia ixx="0.015" iyy="0.0375" izz="0.0375" ixy="0" ixz="0" iyz="0"/>
	</inertial>
  </link>

  <joint name="chair_back_joint" type="fixed">
	<axis xyz="1 0 0"/>
	<parent link="chair_spine"/>
	<child link="chair_back"/>
	<origin rpy="0 0 0" xyz="0.0 0.0 0.225"/>
  </joint>

  <!-- ********************************* 6f. Arm Support (Left)********************************** -->

  <link name="arm_left">
	<visual>
	  <geometry>
		<box size="0.45 0.075 0.03"/>
	  </geometry> 	  
	</visual>
	
	<collision>
	  <geometry>
		<box size="0.45 0.075 0.03"/>
	  </geometry>
	</collision>

	<inertial>
	  <mass value="0.1"/>
	  <inertia ixx="0.015" iyy="0.0375" izz="0.0375" ixy="0" ixz="0" iyz="0"/>
	</inertial>
  </link>

  <joint name="arm_left_joint" type="fixed">
	<axis xyz="1 0 0"/>
	<parent link="arm_brace_left"/>
	<child link="arm_left"/>
	<origin rpy="0 0 0" xyz="0.2 0.025 0.125"/>
  </joint>

  <link name="arm_brace_left">
	<visual>
	  <geometry>
		<box size="0.05 0.03 0.25"/>
	  </geometry> 	  
	</visual>
	
	<collision>
	  <geometry>
		<box size="0.05 0.025 0.25"/>
	  </geometry>
	</collision>

	<inertial>
	  <mass value="0.1"/>
	  <inertia ixx="0.015" iyy="0.0375" izz="0.0375" ixy="0" ixz="0" iyz="0"/>
	</inertial>
  </link>

  <joint name="arm_brace_left_joint" type="fixed">
	<axis xyz="1 0 0"/>
	<parent link="chair_seat"/>
	<child link="arm_brace_left"/>
	<origin rpy="0 0 0" xyz="-0.2 0.225 0.1"/>
  </joint>

  <!-- ******************************** 6g. Arm Support (Right) ********************************* -->

  <link name="arm_right">
	<visual>
	  <geometry>
		<box size="0.45 0.075 0.03"/>
	  </geometry> 	  
	</visual>
	
	<collision>
	  <geometry>
		<box size="0.45 0.075 0.03"/>
	  </geometry>
	</collision>

	<inertial>
	  <mass value="0.1"/>
	  <inertia ixx="0.015" iyy="0.0375" izz="0.0375" ixy="0" ixz="0" iyz="0"/>
	</inertial>
  </link>

  <joint name="arm_right_joint" type="fixed">
	<axis xyz="1 0 0"/>
	<parent link="arm_brace_right"/>
	<child link="arm_right"/>
	<origin rpy="0 0 0" xyz="0.2 -0.025 0.125"/>
  </joint>


  <link name="arm_brace_right">
	<visual>
	  <geometry>
		<box size="0.05 0.03 0.25"/>
	  </geometry> 	  
	</visual>
	
	<collision>
	  <geometry>
		<box size="0.05 0.025 0.25"/>
	  </geometry>
	</collision>

	<inertial>
	  <mass value="0.1"/>
	  <inertia ixx="0.015" iyy="0.0375" izz="0.0375" ixy="0" ixz="0" iyz="0"/>
	</inertial>
  </link>

  <joint name="arm_brace_right_joint" type="fixed">
	<axis xyz="1 0 0"/>
	<parent link="chair_seat"/>
	<child link="arm_brace_right"/>
	<origin rpy="0 0 0" xyz="-0.2 -0.225 0.1"/>
  </joint>

  <!-- ****************************************** 6. END ****************************************** -->

  <!-- ************************************** 7. HOKUYO MODEL ************************************* -->

  <!--   
  The following is a chair made for the powered wheelchair base, created above.
  This is my own model and design. Although it is basic, the model was planned
  using weights and sizes of the Jazzy Select 6 powered wheelchair.
  -->

  <link name="hokuyo_main">
	<visual>
	  <geometry>
		<box size="0.1 0.1 0.1"/>
	  </geometry>
	</visual>

	<collision>
	  <geometry>
		<box size="0.1 0.1 0.1"/>
	  </geometry>
	</collision>

	<inertial>
	  <mass value="1e-5" />
	  <origin xyz="0 0 0" rpy="0 0 0"/>
	  <inertia ixx="1e-6" ixy="0" ixz="0" iyy="1e-6" iyz="0" izz="1e-6" />
	</inertial>
  </link>

  <joint name="hokuyo_main_joint" type="fixed">
	<axis xyz="0 1 0" />
	<origin xyz="0.3 0.0 0.1" rpy="0 0 0"/>
	<parent link="base_link"/>
	<child link="hokuyo_main"/>
  </joint>

  <link name="hokuyo_main_pointer">
	<visual>
	  <geometry>
		<sphere radius="0.02"/>
	  </geometry>
	</visual>

	<collision>
	  <geometry>
		<sphere radius="0.02"/>
	  </geometry>
	</collision>

	<inertial>
	  <mass value="1e-5" />
	  <origin xyz="0 0 0" rpy="0 0 0"/>
	  <inertia ixx="1e-6" ixy="0" ixz="0" iyy="1e-6" iyz="0" izz="1e-6" />
	</inertial>
  </link>

  <joint name="hokuyo_main_pointer_joint" type="fixed">
	<axis xyz="0 1 0" />
	<origin xyz="0.05 0.0 0.0" rpy="0 0 0"/>
	<parent link="hokuyo_main"/>
	<child link="hokuyo_main_pointer"/>
  </joint>

  <!-- ****************************************** 7. END ****************************************** -->

  <!-- ************************************* 8. HOKUYO PLUGIN ************************************* -->

  <gazebo reference="hokuyo_main">
	<sensor type="ray" name="head_hokuyo_sensor">

	  <pose>0 0 0 0 0 0</pose>
	  <visualize>false</visualize>
	  <update_rate>40</update_rate>

	  <ray>

		<scan>
		  <horizontal>
			<samples>720</samples>
			<resolution>1</resolution>
			<min_angle>-1.570796</min_angle>
			<max_angle>1.570796</max_angle>
		  </horizontal>
		</scan>

		<range>
		  <min>0.10</min>
		  <max>30.0</max>
		  <resolution>0.01</resolution>
		</range>


		<noise>
		  <type>gaussian</type>
		  <!-- Noise parameters based on published spec for Hokuyo laser
			   achieving "+-30mm" accuracy at range < 10m.  A mean of 0.0m and
			   stddev of 0.01m will put 99.7% of samples within 0.03m of the true
			   reading. -->
		  <mean>0.0</mean>
		  <stddev>0.01</stddev>
		</noise>

	  </ray>

	  <plugin name="gazebo_ros_head_hokuyo_controller" filename="libgazebo_ros_laser.so">
		<topicName>scan</topicName>
		<frameName>hokuyo_main</frameName>
	  </plugin>

	</sensor>
  </gazebo>

  <!-- ****************************************** 8. END ****************************************** -->

</robot>